<?xml version="1.0"?>
<robot name="ebot" xmlns:xacro="http://ros.org/wiki/xacro">

<!-- add dummy link -->
<link name="base_footprint">
  <visual>
    <origin xyz="0 0 0" rpy="0 0 0"/>
  </visual>
</link>
<joint name="base_footprint_joint" type="fixed">
  <origin xyz="0 0 0" rpy="0 0 0"/>
  <parent link="base_footprint"/>
  <child link="base_link"/>
  
</joint>

<link
name="base_link">
<inertial>
  <origin
    xyz="0.0027952188640647 0.000593932617623182 0.0999652164657865"
    rpy="0 0 0" />
  <mass
    value="46.4238827815078" />
  <inertia
    ixx="2.60450701064623"
    ixy="0.00014390840072613"
    ixz="0.0198394173257472"
    iyy="6.0452234961657"
    iyz="0.0037793554106539"
    izz="7.53481871544823" />
</inertial>
<visual>
  <origin
    xyz="0 0 0"
    rpy="0 0 0" />
  <geometry>
    <mesh
      filename="package://ebot_description/meshes/base_link.STL" />
  </geometry>
  <material
    name="">
    <color
      rgba="0.898039215686275 0.917647058823529 0.929411764705882 1" />
  </material>
</visual>
<collision>
  <origin
    xyz="0 0 0"
    rpy="0 0 0" />
  <geometry>
    <mesh
      filename="package://ebot_description/meshes/base_link.STL" />
  </geometry>
</collision>
</link>
<link
name="left_front_wheel_link">
<inertial>
  <origin
    xyz="-4.68760487704056E-07 -2.28374647293344E-07 -2.94321382321439E-07"
    rpy="0 0 0" />
  <mass
    value="2.60326183430052" />
  <inertia
    ixx="0.0461603249103458"
    ixy="-1.22822868087476E-07"
    ixz="-5.31053411777052E-09"
    iyy="0.0461605171491883"
    iyz="-4.5121849783274E-09"
    izz="0.0824154653190419" />
</inertial>
<visual>
  <origin
    xyz="0 0 0"
    rpy="0 0 0" />
  <geometry>
    <mesh
      filename="package://ebot_description/meshes/left_front_wheel_link.STL" />
  </geometry>
  <material
    name="">
    <color
      rgba="0.384313725490196 0.384313725490196 0.384313725490196 1" />
  </material>
</visual>
<collision>
  <origin
    xyz="0 0 0"
    rpy="0 0 0" />
  <geometry>
    <mesh
      filename="package://ebot_description/meshes/left_front_wheel_link.STL" />
  </geometry>
</collision>
</link>
<joint
name="left_front_wheel_joint"
type="continuous">
<origin
  xyz="0.357389989983846 0.378462296270025 0.00204010952166838"
  rpy="-1.5707963267949 0 0" />
<parent
  link="base_link" />
<child
  link="left_front_wheel_link" />
<axis
  xyz="0 0 -1" />
<limit
  effort="1"
  velocity="1" />
</joint>
<link
name="left_rear_wheel_link">
<inertial>
  <origin
    xyz="-1.39942490928746E-07 5.02302173768961E-07 -2.94321382265927E-07"
    rpy="0 0 0" />
  <mass
    value="2.60326183430052" />
  <inertia
    ixx="0.0461605545192154"
    ixy="8.0653377264343E-08"
    ixz="-3.47868142671829E-09"
    iyy="0.0461602875403188"
    iyz="6.03824158376945E-09"
    izz="0.0824154653190419" />
</inertial>
<visual>
  <origin
    xyz="0 0 0"
    rpy="0 0 0" />
  <geometry>
    <mesh
      filename="package://ebot_description/meshes/left_rear_wheel_link.STL" />
  </geometry>
  <material
    name="">
    <color
      rgba="0.384313725490196 0.384313725490196 0.384313725490196 1" />
  </material>
</visual>
<collision>
  <origin
    xyz="0 0 0"
    rpy="0 0 0" />
  <geometry>
    <mesh
      filename="package://ebot_description/meshes/left_rear_wheel_link.STL" />
  </geometry>
</collision>
</link>
<joint
name="left_rear_wheel_joint"
type="continuous">
<origin
  xyz="-0.359410010016153 0.378462296270025 0.00204010952166891"
  rpy="-1.5707963267949 0 0" />
<parent
  link="base_link" />
<child
  link="left_rear_wheel_link" />
<axis
  xyz="0 0 -1" />
<limit
  effort="1"
  velocity="1" />
</joint>
<link
name="right_front_wheel_link">
<inertial>
  <origin
    xyz="1.50267536525028E-07 -4.99310566422564E-07 2.94321382321439E-07"
    rpy="0 0 0" />
  <mass
    value="2.60326183430053" />
  <inertia
    ixx="0.0461605510937002"
    ixy="8.60684227760523E-08"
    ixz="-2.88232883474286E-10"
    iyy="0.0461602909658341"
    iyz="6.96265090730293E-09"
    izz="0.082415465319042" />
</inertial>
<visual>
  <origin
    xyz="0 0 0"
    rpy="0 0 0" />
  <geometry>
    <mesh
      filename="package://ebot_description/meshes/right_front_wheel_link.STL" />
  </geometry>
  <material
    name="">
    <color
      rgba="0.384313725490196 0.384313725490196 0.384313725490196 1" />
  </material>
</visual>
<collision>
  <origin
    xyz="0 0 0"
    rpy="0 0 0" />
  <geometry>
    <mesh
      filename="package://ebot_description/meshes/right_front_wheel_link.STL" />
  </geometry>
</collision>
</link>
<joint
name="right_front_wheel_joint"
type="continuous">
<origin
  xyz="0.357389989983846 -0.378937703729975 0.0020401095216685"
  rpy="1.5707963267949 0 0" />
<parent
  link="base_link" />
<child
  link="right_front_wheel_link" />
<axis
  xyz="0 0 1" />
<limit
  effort="1"
  velocity="1" />
</joint>
<link
name="right_rear_wheel_link">
<inertial>
  <origin
    xyz="2.46028976969015E-07 4.59740271012421E-07 2.94321382265927E-07"
    rpy="0 0 0" />
  <mass
    value="2.60326183430053" />
  <inertia
    ixx="0.0461605075401993"
    ixy="-1.2977035561121E-07"
    ixz="-4.71079753246785E-09"
    iyy="0.046160334519335"
    iyz="-5.13517015215281E-09"
    izz="0.0824154653190419" />
</inertial>
<visual>
  <origin
    xyz="0 0 0"
    rpy="0 0 0" />
  <geometry>
    <mesh
      filename="package://ebot_description/meshes/right_rear_wheel_link.STL" />
  </geometry>
  <material
    name="">
    <color
      rgba="0.384313725490196 0.384313725490196 0.384313725490196 1" />
  </material>
</visual>
<collision>
  <origin
    xyz="0 0 0"
    rpy="0 0 0" />
  <geometry>
    <mesh
      filename="package://ebot_description/meshes/right_rear_wheel_link.STL" />
  </geometry>
</collision>
</link>
<joint
name="right_rear_wheel_joint"
type="continuous">
<origin
  xyz="-0.359410010016154 -0.378937703729975 0.00204010952166859"
  rpy="1.5707963267949 0 0" />
<parent
  link="base_link" />
<child
  link="right_rear_wheel_link" />
<axis
  xyz="0 0 1" />
<limit
  effort="1"
  velocity="1" />
</joint>
<link
name="lidar_link">
<inertial>
  <origin
    xyz="4.83270678952596E-06 -1.55297993250501E-07 -0.00698644223321671"
    rpy="0 0 0" />
  <mass
    value="0.557223846413529" />
  <inertia
    ixx="0.000784129291358531"
    ixy="-1.47921090233953E-08"
    ixz="1.01569725804807E-07"
    iyy="0.00078408820141775"
    iyz="-3.26392129131928E-09"
    izz="0.000479859162947622" />
</inertial>
<visual>
  <origin
    xyz="0 0 0"
    rpy="0 0 0" />
  <geometry>
    <mesh
      filename="package://ebot_description/meshes/lidar_link.STL" />
  </geometry>
  <material
    name="">
    <color
      rgba="1 1 1 1" />
  </material>
</visual>
<collision>
  <origin
    xyz="0 0 0"
    rpy="0 0 0" />
  <geometry>
    <mesh
      filename="package://ebot_description/meshes/lidar_link.STL" />
  </geometry>
</collision>
</link>
<joint
name="lidar_joint"
type="fixed">
<origin
  xyz="0.322389989983846 0 0.335120109521668"
  rpy="0 0 0" />
<parent
  link="base_link" />
<child
  link="lidar_link" />
<axis
  xyz="0 0 0" />
</joint>
<link
name="bot_cam_link">
<inertial>
  <origin
    xyz="0.0126246506920943 -0.000371155294488475 0.0189997321058511"
    rpy="0 0 0" />
  <mass
    value="0.490726603573483" />
  <inertia
    ixx="0.00252193159143276"
    ixy="-2.32833560497533E-06"
    ixz="1.51280788358069E-09"
    iyy="0.000201425062094394"
    iyz="-1.01893502559056E-10"
    izz="0.00260579562535369" />
</inertial>
<visual>
  <origin
    xyz="0 0 0"
    rpy="0 0 0" />
  <geometry>
    <mesh
      filename="package://ebot_description/meshes/bot_cam_link.STL" />
  </geometry>
  <material
    name="">
    <color
      rgba="0.796078431372549 0.823529411764706 0.937254901960784 1" />
  </material>
</visual>
<collision>
  <origin
    xyz="0 0 0"
    rpy="0 0 0" />
  <geometry>
    <mesh
      filename="package://ebot_description/meshes/bot_cam_link.STL" />
  </geometry>
</collision>
</link>
<joint
name="bot_cam_joint"
type="fixed">
<origin
  xyz="0.488989989983846 0 0.226024336617731"
  rpy="0 0 0" />
<parent
  link="base_link" />
<child
  link="bot_cam_link" />
<axis
  xyz="0 0 0" />
</joint>
<link
name="manipulator_base_link">
<inertial>
  <origin
    xyz="7.22487927756749E-06 -0.000468809221647937 0.0184342922644863"
    rpy="0 0 0" />
  <mass
    value="0.72308351147494" />
  <inertia
    ixx="0.00119721400625643"
    ixy="3.7587973606807E-08"
    ixz="8.31308767977888E-08"
    iyy="0.00116917959377857"
    iyz="3.04764040508186E-07"
    izz="0.0021901549215767" />
</inertial>
<visual>
  <origin
    xyz="0 0 0"
    rpy="0 0 0" />
  <geometry>
    <mesh
      filename="package://ebot_description/meshes/manipulator_base_link.STL" />
  </geometry>
  <material
    name="">
    <color
      rgba="1 1 1 1" />
  </material>
</visual>
<collision>
  <origin
    xyz="0 0 0"
    rpy="0 0 0" />
  <geometry>
    <mesh
      filename="package://ebot_description/meshes/manipulator_base_link.STL" />
  </geometry>
</collision>
</link>
<joint
name="manipulator_base_joint"
type="fixed">
<origin
  xyz="-0.284510010016153 0 0.279240109521669"
  rpy="0 0 -1.5707963267949" />
<parent
  link="base_link" />
<child
  link="manipulator_base_link" />
<axis
  xyz="0 0 0" />
<limit
  lower="0"
  upper="0"
  effort="0"
  velocity="0" />
</joint>
<link
name="joint1_arm_link">
<inertial>
  <origin
    xyz="1.38461781346249E-06 0.0116180920562969 0.116489279738492"
    rpy="0 0 0" />
  <mass
    value="0.313514078484624" />
  <inertia
    ixx="0.00117090749560625"
    ixy="-9.00047295778901E-08"
    ixz="6.7698985696991E-09"
    iyy="0.00109341087696266"
    iyz="-8.76480154207982E-05"
    izz="0.00103229346689333" />
</inertial>
<visual>
  <origin
    xyz="0 0 0"
    rpy="0 0 0" />
  <geometry>
    <mesh
      filename="package://ebot_description/meshes/joint1_arm_link.STL" />
  </geometry>
  <material
    name="">
    <color
      rgba="0.698039215686274 0.698039215686274 0.698039215686274 1" />
  </material>
</visual>
<collision>
  <origin
    xyz="0 0 0"
    rpy="0 0 0" />
  <geometry>
    <mesh
      filename="package://ebot_description/meshes/joint1_arm_link.STL" />
  </geometry>
</collision>
</link>
<joint
name="joint1_arm_joint"
type="revolute">
<origin
  xyz="0 0 0"
  rpy="0 0 0" />
<parent
  link="manipulator_base_link" />
<child
  link="joint1_arm_link" />
<axis
  xyz="0 0 1" />
<limit
  lower="-3.14"
  upper="3.14"
  effort="1"
  velocity="1" />
</joint>
<link
name="joint2_arm_link">
<inertial>
  <origin
    xyz="2.50658315433951E-06 0.250961502622498 0.170341093161932"
    rpy="0 0 0" />
  <mass
    value="0.887819208060646" />
  <inertia
    ixx="0.0463631653033532"
    ixy="-2.40506762705046E-06"
    ixz="-3.14593436315637E-07"
    iyy="0.00205949782389763"
    iyz="-0.00042517000166615"
    izz="0.0461700728944617" />
</inertial>
<visual>
  <origin
    xyz="0 0 0"
    rpy="0 0 0" />
  <geometry>
    <mesh
      filename="package://ebot_description/meshes/joint2_arm_link.STL" />
  </geometry>
  <material
    name="">
    <color
      rgba="0.698039215686274 0.698039215686274 0.698039215686274 1" />
  </material>
</visual>
<collision>
  <origin
    xyz="0 0 0"
    rpy="0 0 0" />
  <geometry>
    <mesh
      filename="package://ebot_description/meshes/joint2_arm_link.STL" />
  </geometry>
</collision>
</link>
<joint
name="joint2_arm_joint"
type="revolute">
<origin
  xyz="0 0 0.128"
  rpy="1.5707963267949 0 -3.14159265358979" />
<parent
  link="joint1_arm_link" />
<child
  link="joint2_arm_link" />
<axis
  xyz="0 0 1" />
<limit
  lower="-3.14"
  upper="3.14"
  effort="1"
  velocity="1" />
</joint>
<link
name="joint3_arm_link">
<inertial>
  <origin
    xyz="0.256850704916233 3.24801653422597E-06 -0.0514156232152406"
    rpy="0 0 0" />
  <mass
    value="0.473747304850832" />
  <inertia
    ixx="0.000614889099940531"
    ixy="2.91059304924887E-07"
    ixz="9.68468303771167E-06"
    iyy="0.0203299993634788"
    iyz="-5.61271528264537E-08"
    izz="0.0202932054654683" />
</inertial>
<visual>
  <origin
    xyz="0 0 0"
    rpy="0 0 0" />
  <geometry>
    <mesh
      filename="package://ebot_description/meshes/joint3_arm_link.STL" />
  </geometry>
  <material
    name="">
    <color
      rgba="0.698039215686274 0.698039215686274 0.698039215686274 1" />
  </material>
</visual>
<collision>
  <origin
    xyz="0 0 0"
    rpy="0 0 0" />
  <geometry>
    <mesh
      filename="package://ebot_description/meshes/joint3_arm_link.STL" />
  </geometry>
</collision>
</link>
<joint
name="joint3_arm_joint"
type="revolute">
<origin
  xyz="0 0.6129 0"
  rpy="3.14159265358979 0 1.5707963267949" />
<parent
  link="joint2_arm_link" />
<child
  link="joint3_arm_link" />
<axis
  xyz="0 0 1" />
<limit
  lower="-3.14"
  upper="3.14"
  effort="1"
  velocity="1" />
</joint>
<link
name="joint4_arm_link">
<inertial>
  <origin
    xyz="0.00970307932063186 8.53903996976233E-06 0.156305876135859"
    rpy="0 0 0" />
  <mass
    value="0.0742764777363476" />
  <inertia
    ixx="9.01021069694116E-05"
    ixy="4.96505867470301E-09"
    ixz="-9.24586118834107E-06"
    iyy="0.000113727174661903"
    iyz="1.3070845903883E-08"
    izz="0.000105196975640594" />
</inertial>
<visual>
  <origin
    xyz="0 0 0"
    rpy="0 0 0" />
  <geometry>
    <mesh
      filename="package://ebot_description/meshes/joint4_arm_link.STL" />
  </geometry>
  <material
    name="">
    <color
      rgba="0.698039215686274 0.698039215686274 0.698039215686274 1" />
  </material>
</visual>
<collision>
  <origin
    xyz="0 0 0"
    rpy="0 0 0" />
  <geometry>
    <mesh
      filename="package://ebot_description/meshes/joint4_arm_link.STL" />
  </geometry>
</collision>
</link>
<joint
name="joint4_arm_joint"
type="revolute">
<origin
  xyz="0.571600428429073 0 0"
  rpy="-3.14159265358979 0 0" />
<parent
  link="joint3_arm_link" />
<child
  link="joint4_arm_link" />
<axis
  xyz="0 0 1" />
<limit
  lower="-3.14"
  upper="3.14"
  effort="1"
  velocity="1" />
</joint>
<link
name="joint5_arm_link">
<inertial>
  <origin
    xyz="8.61896956622905E-06 -0.00970307951605009 0.108115163639832"
    rpy="0 0 0" />
  <mass
    value="0.0742764824505082" />
  <inertia
    ixx="0.000113727175597417"
    ixy="-5.03937123579651E-09"
    ixz="1.31536254916416E-08"
    iyy="9.01021068960171E-05"
    iyz="9.24586765141591E-06"
    izz="0.000105196973949611" />
</inertial>
<visual>
  <origin
    xyz="0 0 0"
    rpy="0 0 0" />
  <geometry>
    <mesh
      filename="package://ebot_description/meshes/joint5_arm_link.STL" />
  </geometry>
  <material
    name="">
    <color
      rgba="0.698039215686274 0.698039215686274 0.698039215686274 1" />
  </material>
</visual>
<collision>
  <origin
    xyz="0 0 0"
    rpy="0 0 0" />
  <geometry>
    <mesh
      filename="package://ebot_description/meshes/joint5_arm_link.STL" />
  </geometry>
</collision>
</link>
<joint
name="joint5_arm_joint"
type="revolute">
<origin
  xyz="0 0 0.163890710540002"
  rpy="-1.5707963267949 0 -1.5707963267949" />
<parent
  link="joint4_arm_link" />
<child
  link="joint5_arm_link" />
<axis
  xyz="0 0 1" />
<limit
  lower="-3.14"
  upper="3.14"
  effort="1"
  velocity="1" />
</joint>
<link
name="joint6_arm_link">
<inertial>
  <origin
    xyz="-0.00047371839928323 -0.000959574728677914 0.0757659878746429"
    rpy="0 0 0" />
  <mass
    value="0.0177637402876479" />
  <inertia
    ixx="9.10047539466835E-06"
    ixy="8.09176057258494E-09"
    ixz="-4.68378057497596E-08"
    iyy="1.01560489305583E-05"
    iyz="5.11603330067679E-08"
    izz="1.66865782398547E-05" />
</inertial>
<visual>
  <origin
    xyz="0 0 0"
    rpy="0 0 0" />
  <geometry>
    <mesh
      filename="package://ebot_description/meshes/joint6_arm_link.STL" />
  </geometry>
  <material
    name="">
    <color
      rgba="0.698039215686274 0.698039215686274 0.698039215686274 1" />
  </material>
</visual>
<collision>
  <origin
    xyz="0 0 0"
    rpy="0 0 0" />
  <geometry>
    <mesh
      filename="package://ebot_description/meshes/joint6_arm_link.STL" />
  </geometry>
</collision>
</link>
<joint
name="joint6_link_joint"
type="revolute">
<origin
  xyz="0 0 0.115700000000003"
  rpy="1.5707963267949 0 0" />
<parent
  link="joint5_arm_link" />
<child
  link="joint6_arm_link" />
<axis
  xyz="0 0 -1" />
<limit
  lower="-3.14"
  upper="3.14"
  effort="1"
  velocity="1" />
</joint>
<link
name="manipulator_cam_link">
<inertial>
  <origin
    xyz="0.000371155294497605 -0.0189997321058422 0.0210481567476905"
    rpy="0 0 0" />
  <mass
    value="0.490726603573485" />
  <inertia
    ixx="0.000201425062207961"
    ixy="-1.01893912384699E-10"
    ixz="2.32833560503236E-06"
    iyy="0.00260579562535371"
    iyz="-1.51280788018831E-09"
    izz="0.00252193159154635" />
</inertial>
<visual>
  <origin
    xyz="0 0 0"
    rpy="0 0 0" />
  <geometry>
    <mesh
      filename="package://ebot_description/meshes/manipulator_cam_link.STL" />
  </geometry>
  <material
    name="">
    <color
      rgba="0.796078431372549 0.823529411764706 0.937254901960784 1" />
  </material>
</visual>
<collision>
  <origin
    xyz="0 0 0"
    rpy="0 0 0" />
  <geometry>
    <mesh
      filename="package://ebot_description/meshes/manipulator_cam_link.STL" />
  </geometry>
</collision>
</link>
<joint
name="manipulator_cam_joint"
type="fixed">
<origin
  xyz="-0.05 0 0.070200000000026"
  rpy="0 0 -1.5707963267949" />
<parent
  link="joint6_arm_link" />
<child
  link="manipulator_cam_link" />
<axis
  xyz="0 0 0" />
</joint>
<link
name="end_effector_link">
<inertial>
  <origin
    xyz="2.56412550443181E-13 1.28801020828906E-05 0.010081299422847"
    rpy="0 0 0" />
  <mass
    value="0.00910566817149649" />
  <inertia
    ixx="3.57910062328938E-06"
    ixy="1.54392728934264E-19"
    ixz="-1.23682875393268E-20"
    iyy="3.5617701227317E-06"
    iyz="1.35827722863776E-09"
    izz="6.48644742391655E-06" />
</inertial>
<visual>
  <origin
    xyz="0 0 0"
    rpy="0 0 0" />
  <geometry>
    <mesh
      filename="package://ebot_description/meshes/end_effector_link.STL" />
  </geometry>
  <material
    name="">
    <color
      rgba="0.698039215686274 0.698039215686274 0.698039215686274 1" />
  </material>
</visual>
<collision>
  <origin
    xyz="0 0 0"
    rpy="0 0 0" />
  <geometry>
    <mesh
      filename="package://ebot_description/meshes/end_effector_link.STL" />
  </geometry>
</collision>
</link>
<joint
name="end_effector_joint"
type="revolute">
<origin
  xyz="0 0 0.092200000000002"
  rpy="0 0 0" />
<parent
  link="joint6_arm_link" />
<child
  link="end_effector_link" />
<axis
  xyz="0 0 1" />
  <limit
  lower="0.0"
  upper="0.01"
  effort="1"
  velocity="1" />
</joint>

	<ros2_control name="GazeboSystem" type="system">
		<hardware>
			<plugin>gazebo_ros2_control/GazeboSystem</plugin>
		</hardware>
	  
    <joint name="left_front_wheel_joint">
			<command_interface name="velocity">
				<param name="min">-1000.0</param>
				<param name="max">1000.0</param>
			</command_interface>
			<state_interface name="position"/>
			<state_interface name="velocity"/>
		</joint>
		
		<joint name="left_rear_wheel_joint">
			<command_interface name="velocity">
				<param name="min">-1000.0</param>
				<param name="max">1000.0</param>
			</command_interface>
			<state_interface name="position"/>
			<state_interface name="velocity"/>
		</joint>

		<joint name="right_front_wheel_joint">
			<command_interface name="velocity">
				<param name="min">-1000.0</param>
				<param name="max">1000.0</param>
			</command_interface>
			<state_interface name="position"/>
			<state_interface name="velocity"/>
      
		</joint>

		<joint name="right_rear_wheel_joint">
			<command_interface name="velocity">
				<param name="min">-1000.0</param>
				<param name="max">1000.0</param>
			</command_interface>
			<state_interface name="position"/>
			<state_interface name="velocity"/>
		</joint> 
	    
		<joint name="joint1_arm_joint">
			<command_interface name="position">
				<param name="min">-3.14</param>
				<param name="max">3.14</param>
			</command_interface>
			<state_interface name="position"/>
			<state_interface name="velocity"/>
		</joint>

		<joint name="joint2_arm_joint">
			<command_interface name="position">
				<param name="min">-3.14</param>
				<param name="max">3.14</param>
			</command_interface>
			<state_interface name="position"/>
			<state_interface name="velocity"/>
		</joint>

		<joint name="joint3_arm_joint">
			<command_interface name="position">
				<param name="min">-3.14</param>
				<param name="max">3.14</param>
			</command_interface>
			<state_interface name="position"/>
			<state_interface name="velocity"/>
		</joint>

		<joint name="joint4_arm_joint">
			<command_interface name="position">
				<param name="min">-3.14</param>
				<param name="max">3.14</param>
			</command_interface>
			<state_interface name="position"/>
			<state_interface name="velocity"/>
		</joint>

		<joint name="joint5_arm_joint">
			<command_interface name="position">
				<param name="min">-3.14</param>
				<param name="max">3.14</param>
			</command_interface>
			<state_interface name="position"/>
			<state_interface name="velocity"/>
		</joint>

		<joint name="joint6_link_joint">
			<command_interface name="position">
				<param name="min">-6.28</param>
				<param name="max">6.28</param>
			</command_interface>
			<state_interface name="position"/>
			<state_interface name="velocity"/>
		</joint>

		<joint name="joint1_arm_joint">
			<command_interface name="velocity">
			<param name="min">-1000</param>
			<param name="max">1000</param>
			</command_interface>
			<state_interface name="position">
			</state_interface>
			<state_interface name="velocity"/>
			</joint>
		
		<joint name="joint2_arm_joint">
		<command_interface name="velocity">
		<param name="min">-1000</param>
		<param name="max">1000</param>
		</command_interface>
		<state_interface name="position">
		</state_interface>
		<state_interface name="velocity"/>
		</joint>

		<joint name="joint3_arm_joint">
			<command_interface name="velocity">
			<param name="min">-1000</param>
			<param name="max">1000</param>
			</command_interface>
			<state_interface name="position">
			</state_interface>
			<state_interface name="velocity"/>
			</joint>

		<joint name="joint4_arm_joint">
			<command_interface name="velocity">
			<param name="min">-1000</param>
			<param name="max">1000</param>
			</command_interface>
			<state_interface name="position">
			</state_interface>
			<state_interface name="velocity"/>
			</joint>

		<joint name="joint5_arm_joint">
			<command_interface name="velocity">
			<param name="min">-1000</param>
			<param name="max">1000</param>
			</command_interface>
			<state_interface name="position">
			</state_interface>
			<state_interface name="velocity"/>
			</joint>

		<joint name="joint6_link_joint">
			<command_interface name="velocity">
			<param name="min">-1000</param>
			<param name="max">1000</param>
			</command_interface>
			<state_interface name="position">
			</state_interface>
			<state_interface name="velocity"/>
			</joint>

	   
		</ros2_control>

		<gazebo>
			<plugin filename="libgazebo_ros2_control.so" name="gazebo_ros2_control">
				<parameters>$(find ebot_description)/config/control.yaml</parameters>
			</plugin>
		</gazebo>

<!-- 
    <gazebo reference="left_front_wheel_link">
      <kp>1000000.0</kp> 
      <kd>1000000.0</kd>
      <mu1>1.0</mu1>
      <mu2>1.0</mu2>
      <minDepth>0.02</minDepth>
      <material>Gazebo/Black</material>
  </gazebo>
  <gazebo reference="right_front_wheel_link">
    <kp>1000000.0</kp> 
    <kd>1000000.0</kd>
    <mu1>1.0</mu1>
    <mu2>1.0</mu2>
    <minDepth>0.02</minDepth>
      <material>Gazebo/Black</material>
  </gazebo>
  <gazebo reference="left_rear_wheel_link">
    <kp>1000000.0</kp> 
    <kd>1000000.0</kd>
    <mu1>1.0</mu1>
    <mu2>1.0</mu2>
    <minDepth>0.02</minDepth>
      <material>Gazebo/Black</material>
  </gazebo>
  <gazebo reference="right_rear_wheel_link">
    <kp>1000000.0</kp>
    <kd>1000000.0</kd>
    <mu1>1.0</mu1>
    <mu2>1.0</mu2>
    <minDepth>0.02</minDepth>
      <material>Gazebo/Black</material>
  </gazebo> -->

    <!-- <gazebo>
      <plugin name='skid_steer_drive' filename='libgazebo_ros_diff_drive.so'>
        <ros>
          <namespace>/</namespace>
  
          <remapping>odom:=wheel_odom</remapping>
        </ros>
  
        <update_rate>500</update_rate>
  
        <num_wheel_pairs>2</num_wheel_pairs>
  
        <left_joint>left_front_wheel_joint</left_joint>
        <right_joint>right_front_wheel_joint</right_joint>
  
        <left_joint>left_rear_wheel_joint</left_joint>
        <right_joint>right_rear_wheel_joint</right_joint>
  
        <wheel_separation>0.76</wheel_separation>
        <wheel_separation>0.76</wheel_separation>
  
        <wheel_diameter>0.461</wheel_diameter>
        <wheel_diameter>0.461</wheel_diameter>
  
        <max_wheel_torque>50</max_wheel_torque>
        <max_wheel_acceleration>1.0</max_wheel_acceleration>
  
        <publish_odom>true</publish_odom>
        <publish_odom_tf>false</publish_odom_tf>
        <publish_wheel_tf>true</publish_wheel_tf>
  
        <odometry_frame>odom</odometry_frame>
        <robot_base_frame>base_link</robot_base_frame>
  
      </plugin>
  </gazebo> -->
  
	<!-- sensors -->

	<!-- lidar -->
	<gazebo reference="lidar_link">
		<sensor name="lidar" type="ray">
		  <pose>0.0 0.0 0.0 0 0 0</pose>
		  <always_on>true</always_on>
		  <visualize>false</visualize>
		  <update_rate>20</update_rate>
		  <ray>
			<scan>
			  <horizontal>
				<samples>360</samples>
				<resolution>1.00000</resolution>
				<min_angle>0.000000</min_angle>
				<max_angle>6.280000</max_angle>
			  </horizontal>
			</scan>
			<range>
			  <min>0.120000</min>
			  <max>10.0</max>
			  <resolution>0.015000</resolution>
			</range>
			<noise>
			  <type>gaussian</type>
			  <mean>0.0</mean>
			  <stddev>0.01</stddev>
			</noise>
		  </ray>
		  <plugin name="scan" filename="libgazebo_ros_ray_sensor.so">
			<ros>
			  <remapping>~/out:=scan</remapping>
			</ros>
			<output_type>sensor_msgs/LaserScan</output_type>
			<frame_name>lidar_link</frame_name>
		  </plugin>
		</sensor>
	  </gazebo>


	  
  <gazebo reference="base_link">
    <gravity>true</gravity>
    <sensor name="imu_sensor" type="imu">
      <always_on>true</always_on>
      <update_rate>100</update_rate>
      <visualize>false</visualize>
      <topic>__default_topic__</topic>
      <plugin filename="libgazebo_ros_imu_sensor.so" name="imu_plugin">
        <topicName>imu</topicName>
        <bodyName>base_link</bodyName>
        <updateRateHZ>10.0</updateRateHZ>
        <gaussianNoise>0.0</gaussianNoise>
        <xyzOffset>0 0 0</xyzOffset>
        <rpyOffset>0 0 0</rpyOffset>
        <frameName>base_link</frameName>
        <initialOrientationAsReference>false</initialOrientationAsReference>
      </plugin>
      <pose>0 0 0 0 0 0</pose>
    </sensor>
  </gazebo>

  <gazebo>
    <plugin name='vacuum_gripper' filename='libgazebo_ros_vacuum_gripper.so'>
    
      <!-- This part can be commented out if not required -->
      <ros>
    
      <!-- Add a namespace -->
    
      <namespace>/</namespace>
    
      <!-- Remapping service and topic names -->
      <remapping>switch:=custom_switch</remapping>
      <remapping>grasping:=custom_grasping</remapping>
      </ros>
    
      <!-- Link associated with gripper -->
      <link_name>end_effector_link</link_name>
    
      <!-- Max distance to attract entities -->
      <max_distance>10.0</max_distance>
    
      <!-- List of entities to be not attracted by the gripper -->
      <fixed>ground_plane</fixed>
      <fixed>wall</fixed>
    
    </plugin>
  </gazebo>

  <gazebo reference="manipulator_cam_link">
    <sensor name="cam" type="depth">
        <always_on>true</always_on>
        <update_rate>15</update_rate>
        <pose>0 0 0 0 0 0</pose>
        <camera name="realsense_depth_camera">
            <horizontal_fov>1.46608</horizontal_fov>
            <image>
                <width>1000</width>
                <height>1000</height>
                <format>B8G8R8</format>
            </image>
            <clip>
                <near>0.05</near>
                <far>8</far>
            </clip>
        </camera>
        <plugin name="intel_realsense_d430_depth_driver" filename="libgazebo_ros_camera.so">
            <ros>
                <namespace>/arm</namespace>
                <remapping>cam/image_raw:=color/image_raw</remapping>
                <remapping>cam/depth/image_raw:=depth/image_rect_raw</remapping>
                <remapping>cam/camera_info:=camera_info</remapping>
                <remapping>cam/depth/camera_info:=depth/camera_info</remapping>
                <remapping>cam/points:=depth/points</remapping>
            </ros>
            <camera_name>arm_cam</camera_name>
            <frame_name>manipulator_cam_link</frame_name>
            <hack_baseline>0.07</hack_baseline>
            <min_depth>0.05</min_depth>
            <max_depth>8.0</max_depth>
        </plugin>
    </sensor>
</gazebo>



<gazebo>
  <plugin filename="libodometry_plugin.so" name="odometry_plugin">
]    <ros>
      <remapping>odom:=wheel_odom</remapping>

  </ros>
  <frame>base_footprint</frame>
    <world_frame>odom</world_frame>
  </plugin>
</gazebo>

<gazebo reference="bot_cam_link">
  <sensor name="cam" type="depth">
      <always_on>true</always_on>
      <update_rate>15</update_rate>
      <pose>0 0 0 0 0 0</pose>
      <camera name="realsense_depth_camera">
          <horizontal_fov>1.46608</horizontal_fov>
          <image>
              <width>1000</width>
              <height>1000</height>
              <format>B8G8R8</format>
          </image>
          <clip>
              <near>0.05</near>
              <far>12</far>
          </clip>
      </camera>
      <plugin name="intel_realsense_d430_depth_driver" filename="libgazebo_ros_camera.so">
          <ros>
              <namespace>/bot</namespace>
              <remapping>cam/image_raw:=color/image_raw</remapping>
              <remapping>cam/depth/image_raw:=depth/image_rect_raw</remapping>
              <remapping>cam/camera_info:=camera_info</remapping>
              <remapping>cam/depth/camera_info:=depth/camera_info</remapping>
              <remapping>cam/points:=depth/points</remapping>
          </ros>
          <camera_name>bot_cam</camera_name>
          <frame_name>bot_cam_link</frame_name>
          <hack_baseline>0.07</hack_baseline>
          <min_depth>0.05</min_depth>
          <max_depth>12.0</max_depth>
      </plugin>
  </sensor>
</gazebo>


</robot>
